<?xml version="1.0" ?>
<!-- =================================================================================== -->
<!-- |    This document was autogenerated by xacro from fanucm20_robot.urdf.xacro      | -->
<!-- |    EDITING THIS FILE BY HAND IS NOT RECOMMENDED                                 | -->
<!-- =================================================================================== -->
<robot name="fanuc_m20" xmlns:xacro="http://wiki.ros.org/xacro">
  <gazebo>
    <plugin filename="libgazebo_ros_control.so" name="ros_control">
      <!--robotNamespace>/</robotNamespace-->
      <!--robotSimType>gazebo_ros_control/DefaultRobotHWSim</robotSimType-->
      <legacyModeNS>true</legacyModeNS>
    </plugin>
    <!--
    <plugin name="gazebo_ros_power_monitor_controller" filename="libgazebo_ros_power_monitor.so">
      <alwaysOn>true</alwaysOn>
      <updateRate>1.0</updateRate>
      <timeout>5</timeout>
      <powerStateTopic>power_state</powerStateTopic>
      <powerStateRate>10.0</powerStateRate>
      <fullChargeCapacity>87.78</fullChargeCapacity>     
      <dischargeRate>-474</dischargeRate>
      <chargeRate>525</chargeRate>
      <dischargeVoltage>15.52</dischargeVoltage>
      <chargeVoltage>16.41</chargeVoltage>
    </plugin>
-->
  </gazebo>
  <link name="base_link">
    <inertial>
      <origin rpy="0 0 0" xyz="-2.7535E-06 0.00054789 0.02299"/>
      <mass value="1.2345e+01"/>
      <inertia ixx="0.0029215E-04" ixy="2.2046E-07" ixz="-3.4773E-08" iyy="0.0028546E-04" iyz="-7.6362E-06" izz="0.000051176"/>
    </inertial>
    <visual>
      <origin rpy="0 0 0" xyz="0 0 1"/>
      <geometry>
        <mesh filename="../meshes/visual/base_link.stl"/>
      </geometry>
      <material name="">
        <color rgba="0.278431372549 0.278431372549 0.278431372549 1.0"/>
      </material>
    </visual>
    <collision>
      <origin rpy="0 0 0" xyz="0 0 1"/>
      <geometry>
        <mesh filename="../meshes/collision/base_link.stl"/>
      </geometry>
    </collision>
  </link>
  <joint name="shoulder_pan_joint" type="revolute">
    <parent link="base_link"/>
    <child link="shoulder_link"/>
    <origin rpy="0 0 0" xyz="0 0 1.525"/>
    <axis xyz="0 0 1"/>
    <limit effort="0" lower="-3.1415" upper="3.1415" velocity="3.0543"/>
    <dynamics damping="1.0" friction="0.0"/>
  </joint>
  <link name="shoulder_link">
    <inertial>
      <origin rpy="0 0 0" xyz="0.00029287 0.14173 0.54281"/>
      <mass value="10.994e-02"/>
      <inertia ixx="2.2088e-02" ixy="-0.00043922e-02" ixz="-0.0025417e-02" iyy="2.1473e-02" iyz="-0.049088e-02" izz="0.07998e-02"/>
    </inertial>
    <visual>
      <origin rpy="0 0 0" xyz="0 0 0"/>
      <geometry>
        <mesh filename="../meshes/visual/link_1.dae"/>
      </geometry>
      <material name="">
        <color rgba="0.96 0.76 0.13 1.0"/>
      </material>
    </visual>
    <collision>
      <origin rpy="0 0 0" xyz="0 0 0"/>
      <geometry>
        <mesh filename="../meshes/collision/link_1.stl"/>
      </geometry>
    </collision>
  </link>
  <joint name="shoulder_lift_joint" type="revolute">
    <parent link="shoulder_link"/>
    <child link="upper_arm_link"/>
    <origin rpy="0 0 0" xyz="0.150 0 0"/>
    <axis xyz="0 1 0"/>
    <limit effort="330.0" lower="-6.28318530718" upper="6.28318530718" velocity="2.16"/>
    <dynamics damping="1.0" friction="0.0"/>
  </joint>
  <link name="upper_arm_link">
    <inertial>
      <origin rpy="0 0 0" xyz="0.31908 -3.7071E-06 -0.0042956"/>
      <mass value="5.3139e-02"/>
      <inertia ixx="0.0095171e-02" ixy="7.2849E-06" ixz="-6.7014E-06" iyy="0.11411e-02" iyz="-1.1529E-06" izz="0.11411e-02"/>
    </inertial>
    <visual>
      <origin rpy="0 0 0" xyz="0 0 0"/>
      <geometry>
        <mesh filename="../meshes/visual/link_2.dae"/>
      </geometry>
      <material name="">
        <color rgba="0.96 0.76 0.13 1.0"/>
      </material>
    </visual>
    <collision>
      <origin rpy="0 0 0" xyz="0 0 0"/>
      <geometry>
        <mesh filename="../meshes/collision/link_2.stl"/>
      </geometry>
    </collision>
  </link>
  <joint name="elbow_joint" type="revolute">
    <parent link="upper_arm_link"/>
    <child link="forearm_link"/>
    <origin rpy="0 0 0" xyz="0 0 0.790"/>
    <axis xyz="0 -1 0"/>
    <limit effort="150.0" lower="-3.14159265359" upper="3.14159265359" velocity="3.15"/>
    <dynamics damping="1.0" friction="0.0"/>
  </joint>
  <link name="forearm_link">
    <inertial>
      <origin rpy="0 0 0" xyz="0.24431 6.6794E-06 0.12549"/>
      <mass value="3.1022e-02"/>
      <inertia ixx="0.0027288e-02" ixy="-6.2713E-06" ixz="-0.0018082e-02" iyy="0.097825e-02" iyz="3.5731E-07" izz="0.097866"/>
    </inertial>
    <visual>
      <origin rpy="0 0 0" xyz="0 0 0"/>
      <geometry>
        <mesh filename="../meshes/visual/link_3.dae"/>
      </geometry>
      <material name="">
        <color rgba="0.96 0.76 0.13 1.0"/>
      </material>
    </visual>
    <collision>
      <origin rpy="0 0 0" xyz="0 0 0"/>
      <geometry>
        <mesh filename="../meshes/collision/link_3.stl"/>
      </geometry>
    </collision>
  </link>
  <joint name="wrist_1_joint" type="revolute">
    <parent link="forearm_link"/>
    <child link="wrist_1_link"/>
    <origin rpy="0 0 0" xyz="0 0 0.250"/>
    <axis xyz="-1 0 0"/>
    <limit effort="54.0" lower="-6.28318530718" upper="6.28318530718" velocity="3.2"/>
    <dynamics damping="1.0" friction="0.0"/>
  </joint>
  <link name="wrist_1_link">
    <inertial>
      <origin rpy="0 0 0" xyz="-5.2305E-07 -0.00026581 -0.0027894"/>
      <mass value="0.57981e-03"/>
      <inertia ixx="0.00088336e-02" ixy="-6.4251E-09" ixz="-5.1594E-09" iyy="0.00046118e-02" iyz="1.0734E-06" izz="0.00085336e-02"/>
    </inertial>
    <visual>
      <origin rpy="0 0 0" xyz="0 0 0"/>
      <geometry>
        <mesh filename="../meshes/visual/link_4.dae"/>
      </geometry>
      <material name="">
        <color rgba="0.96 0.76 0.13 1.0"/>
      </material>
    </visual>
    <collision>
      <origin rpy="0 0 0" xyz="0 0 0"/>
      <geometry>
        <mesh filename="../meshes/collision/link_4.stl"/>
      </geometry>
    </collision>
  </link>
  <joint name="wrist_2_joint" type="revolute">
    <parent link="wrist_1_link"/>
    <child link="wrist_2_link"/>
    <origin rpy="0 0 0" xyz="0.835 0 0.0"/>
    <axis xyz="0 -1 0"/>
    <limit effort="54.0" lower="-6.28318530718" upper="6.28318530718" velocity="3.2"/>
    <dynamics damping="0.0" friction="0.0"/>
  </joint>
  <link name="wrist_2_link">
    <inertial>
      <origin rpy="0 0 0" xyz="-5.2305E-07 -0.00026581 -0.0027894"/>
      <mass value="0.37981e-03"/>
      <inertia ixx="0.00088336e-02" ixy="-6.4251E-09" ixz="-5.1594E-09" iyy="0.00046118e-02" iyz="1.0734E-06" izz="0.00085336e-02"/>
    </inertial>
    <visual>
      <origin rpy="0 0 0" xyz="0 0 0"/>
      <geometry>
        <mesh filename="../meshes/visual/link_5.dae"/>
      </geometry>
      <material name="">
        <color rgba="0.96 0.76 0.13 1.0"/>
      </material>
    </visual>
    <collision>
      <origin rpy="0 0 0" xyz="0 0 0"/>
      <geometry>
        <mesh filename="../meshes/collision/link_5.stl"/>
      </geometry>
    </collision>
  </link>
  <joint name="wrist_3_joint" type="revolute">
    <parent link="wrist_2_link"/>
    <child link="wrist_3_link"/>
    <origin rpy="0 0 0" xyz="0.1 0 0"/>
    <axis xyz="-1 0 0"/>
    <limit effort="0" lower="-6.2831" upper="6.2831" velocity="6.1959"/>
    <dynamics damping="0.0" friction="0.0"/>
  </joint>
  <link name="wrist_3_link">
    <inertial>
      <origin rpy="0 0 0" xyz="-2.2127E-09 0.00023722 -0.018629"/>
      <mass value="0.13669e-03"/>
      <inertia ixx="6.0946E-07" ixy="9.3663E-12" ixz="-1.3841E-12" iyy="5.9501E-07" iyz="1.9944E-09" izz="9.6981E-07"/>
    </inertial>
    <visual>
      <origin rpy="0 0 0" xyz="0 0 0"/>
      <geometry>
        <mesh filename="../meshes/visual/link_6.dae"/>
      </geometry>
      <material name="">
        <color rgba="0.15 0.15 0.15 1.0"/>
      </material>
    </visual>
    <collision>
      <origin rpy="0 0 0" xyz="0 0 0"/>
      <geometry>
        <mesh filename="../meshes/collision/link_6.stl"/>
      </geometry>
    </collision>
  </link>
  <transmission name="shoulder_pan_trans">
    <type>transmission_interface/SimpleTransmission</type>
    <joint name="shoulder_pan_joint">
      <hardwareInterface>hardware_interface/PositionJointInterface</hardwareInterface>
    </joint>
    <actuator name="shoulder_pan_motor">
      <mechanicalReduction>1</mechanicalReduction>
    </actuator>
  </transmission>
  <transmission name="shoulder_lift_trans">
    <type>transmission_interface/SimpleTransmission</type>
    <joint name="shoulder_lift_joint">
      <hardwareInterface>hardware_interface/PositionJointInterface</hardwareInterface>
    </joint>
    <actuator name="shoulder_lift_motor">
      <mechanicalReduction>1</mechanicalReduction>
    </actuator>
  </transmission>
  <transmission name="elbow_trans">
    <type>transmission_interface/SimpleTransmission</type>
    <joint name="elbow_joint">
      <hardwareInterface>hardware_interface/PositionJointInterface</hardwareInterface>
    </joint>
    <actuator name="elbow_motor">
      <mechanicalReduction>1</mechanicalReduction>
    </actuator>
  </transmission>
  <transmission name="wrist_1_trans">
    <type>transmission_interface/SimpleTransmission</type>
    <joint name="wrist_1_joint">
      <hardwareInterface>hardware_interface/PositionJointInterface</hardwareInterface>
    </joint>
    <actuator name="wrist_1_motor">
      <mechanicalReduction>1</mechanicalReduction>
    </actuator>
  </transmission>
  <transmission name="wrist_2_trans">
    <type>transmission_interface/SimpleTransmission</type>
    <joint name="wrist_2_joint">
      <hardwareInterface>hardware_interface/PositionJointInterface</hardwareInterface>
    </joint>
    <actuator name="wrist_2_motor">
      <mechanicalReduction>1</mechanicalReduction>
    </actuator>
  </transmission>
  <transmission name="wrist_3_trans">
    <type>transmission_interface/SimpleTransmission</type>
    <joint name="wrist_3_joint">
      <hardwareInterface>hardware_interface/PositionJointInterface</hardwareInterface>
    </joint>
    <actuator name="wrist_3_motor">
      <mechanicalReduction>1</mechanicalReduction>
    </actuator>
  </transmission>
  <gazebo reference="shoulder_link">
    <selfCollide>true</selfCollide>
  </gazebo>
  <gazebo reference="upper_arm_link">
    <selfCollide>true</selfCollide>
  </gazebo>
  <gazebo reference="forearm_link">
    <selfCollide>true</selfCollide>
  </gazebo>
  <gazebo reference="wrist_1_link">
    <selfCollide>true</selfCollide>
  </gazebo>
  <gazebo reference="wrist_3_link">
    <selfCollide>true</selfCollide>
  </gazebo>
  <gazebo reference="wrist_2_link">
    <selfCollide>true</selfCollide>
  </gazebo>
  <gazebo reference="ee_link">
    <selfCollide>true</selfCollide>
  </gazebo>
  <!-- base for robot -->
  <link name="fanucbase">
    <inertial>
      <origin rpy="0 0 0" xyz="-2.7535E-06 0.00054789 0.02299"/>
      <mass value="3.2345e+01"/>
      <inertia ixx="0.0029215E-04" ixy="2.2046E-07" ixz="-3.4773E-08" iyy="0.0028546E-04" iyz="-7.6362E-06" izz="0.000051176"/>
    </inertial>
    <visual>
      <origin rpy="0 0 0" xyz="0 0 0"/>
      <geometry>
        <mesh filename="../meshes/visual/base.dae" scale="0.6 0.6 1"/>
      </geometry>
      <material name="">
        <color rgba="0.15 0.15 0.15 1.0"/>
      </material>
    </visual>
    <collision>
      <origin rpy="0 0 0" xyz="0 0 0"/>
      <geometry>
        <mesh filename="../meshes/visual/base.STL" scale="0.6 0.6 1"/>
      </geometry>
    </collision>
  </link>
  <joint name="base_link_base" type="fixed">
    <origin rpy="0 0 0" xyz="-0.35 -0.35 0"/>
    <parent link="base_link"/>
    <child link="fanucbase"/>
  </joint>
  <!--tool link -->
  <link name="tool0">
    <visual>
      <geometry>
        <mesh filename="../meshes/visual/cameratool.STL" scale="0.001 0.001 0.001"/>
      </geometry>
    </visual>
  </link>
  <joint name="tool_joint" type="fixed">
    <origin rpy="1.57079632679 3.14159265359 1.57079632679" xyz="0 0 0"/>
    <parent link="wrist_3_link"/>
    <child link="tool0"/>
  </joint>
  <link name="world"/>
  <joint name="world_joint" type="fixed">
    <parent link="world"/>
    <child link="base_link"/>
    <origin rpy="0.0 0.0 -1.57079632679" xyz="0.0 0.0 0.0"/>
  </joint>
</robot>
