<?xml version="1.0"?>
<robot xmlns:xacro="http://wiki.ros.org/xacro">

<!--
  Author: Kelsey Hawkins
  Contributers: Jimmy Da Silva, Ajit Krisshna N L, Muhammad Asif Rana
-->
  <xacro:include filename="./common_materials.xacro"/>
  <xacro:include filename="./ur.transmission.xacro" />
  <xacro:include filename="./ur.gazebo.xacro" />
  
  <xacro:macro name="cylinder_inertial" params="radius length mass *origin">
    <inertial>
      <mass value="${mass}" />
      <xacro:insert_block name="origin" />
      <inertia ixx="${0.0833333 * mass * (3 * radius * radius + length * length)}" ixy="0.0" ixz="0.0"
        iyy="${0.0833333 * mass * (3 * radius * radius + length * length)}" iyz="0.0"
        izz="${0.5 * mass * radius * radius}" />
    </inertial>
  </xacro:macro>

  <xacro:macro name="auboi5_robot" params="prefix joint_limited
    shoulder_pan_lower_limit:=${-pi}    shoulder_pan_upper_limit:=${pi}
    shoulder_lift_lower_limit:=${-pi}    shoulder_lift_upper_limit:=${pi}
    elbow_joint_lower_limit:=${-pi}    elbow_joint_upper_limit:=${pi}
    wrist_1_lower_limit:=${-pi}    wrist_1_upper_limit:=${pi}
    wrist_2_lower_limit:=${-pi}    wrist_2_upper_limit:=${pi}
    wrist_3_lower_limit:=${-pi}    wrist_3_upper_limit:=${pi}
    transmission_hw_interface:=hardware_interface/PositionJointInterface
    safety_limits:=false safety_pos_margin:=0.15
    safety_k_position:=20">

    <!-- Inertia parameters -->
    

    <!-- These parameters are borrowed from the urcontrol.conf file
        but are not verified for the correct permutation.
        The permutation was guessed by looking at the UR5 parameters.
        Serious use of these parameters needs further inspection. -->
    

    
    <link name="${prefix}base_link" >
      <inertial>
        <origin xyz="-1.4795E-13 0.0015384 0.020951" rpy="0 0 0" />
        <mass value="0.83419" />
        <inertia ixx="0.0014414" ixy="7.8809E-15" ixz="8.5328E-16" iyy="0.0013542" iyz="-1.4364E-05" izz="0.0024659" />
      </inertial>
      <visual>
        <origin xyz="0 0 0" rpy="0 0 0" />
        <geometry>
          <mesh filename="./meshes/aubo_i5/visual/base_link.DAE" />
        </geometry>
        <material name="">
          <color rgba="1 1 1 1" />
        </material>
      </visual>
      <collision>
        <origin xyz="0 0 0" rpy="0 0 0" />
        <geometry>
          <mesh filename="./meshes/aubo_i5/collision/base_link.STL" />
        </geometry>
      </collision>
    </link>

    <joint name="${prefix}shoulder_pan_joint" type="revolute">
      <origin xyz="0 0 0.122" rpy="0 0 3.1416" />
      <parent link="${prefix}base_link" />
      <child link="${prefix}shoulder_link" />
      <axis xyz="0 0 1" />
      <xacro:unless value="${joint_limited}">
        <limit effort="0" lower="-3.1415" upper="3.1415" velocity="3.0543"/>
        <xacro:if value="${safety_limits}">
          <safety_controller soft_lower_limit="${-2.0 * pi + safety_pos_margin}" soft_upper_limit="${2.0 * pi - safety_pos_margin}" k_position="${safety_k_position}" k_velocity="0.0"/>
        </xacro:if>
      </xacro:unless>
      <xacro:if value="${joint_limited}">
        <limit lower="${shoulder_pan_lower_limit}" upper="${shoulder_pan_upper_limit}" effort="330.0" velocity="2.16"/>
        <xacro:if value="${safety_limits}">
          <safety_controller soft_lower_limit="${shoulder_pan_lower_limit + safety_pos_margin}" soft_upper_limit="${shoulder_pan_upper_limit - safety_pos_margin}" k_position="${safety_k_position}" k_velocity="0.0"/>
        </xacro:if>
      </xacro:if>
      <dynamics damping="1.0" friction="0.0"/>
    </joint>

    <link name="${prefix}shoulder_link">
      <inertial>
        <origin xyz="0.0 0.006 -0.002"
                  rpy="0 0 0" />
        <mass value="5.05" />
        <inertia ixx="0.0148"
                  ixy="0"
                  ixz="0"
                  iyy="0.0143"
                  iyz="-0.0"
                  izz="0.0095" />
      </inertial>
      <visual>
        <origin xyz="0 0 0" rpy="0 0 0" />
        <geometry>
          <mesh filename="./meshes/aubo_i5/visual/shoulder_Link.DAE" />
        </geometry>
        <material name="">
          <color rgba="1 1 1 1" />
        </material>
      </visual>
      <collision>
        <origin xyz="0 0 0" rpy="0 0 0" />
        <geometry>
          <mesh filename="./meshes/aubo_i5/collision/shoulder_Link.STL" />
        </geometry>
      </collision>
    </link>

    <joint name="${prefix}shoulder_lift_joint" type="revolute">
      <origin xyz="0 0.1215 0" rpy="-1.5708 -1.5708 0" />
      <parent link="${prefix}shoulder_link" />
      <child link="${prefix}upper_arm_link" />
      <axis xyz="0 0 1" />
      <xacro:unless value="${joint_limited}">
        <limit lower="${-2.0 * pi}" upper="${2.0 * pi}" effort="330.0" velocity="2.16"/>
        <xacro:if value="${safety_limits}">
          <safety_controller soft_lower_limit="${-2.0 * pi + safety_pos_margin}" soft_upper_limit="${2.0 * pi - safety_pos_margin}" k_position="${safety_k_position}" k_velocity="0.0"/>
        </xacro:if>
      </xacro:unless>
      <xacro:if value="${joint_limited}">
        <limit lower="${shoulder_lift_lower_limit}" upper="${shoulder_lift_upper_limit}" effort="330.0" velocity="2.16"/>
        <xacro:if value="${safety_limits}">
          <safety_controller soft_lower_limit="${shoulder_lift_lower_limit + safety_pos_margin}" soft_upper_limit="${shoulder_lift_upper_limit - safety_pos_margin}" k_position="${safety_k_position}" k_velocity="0.0"/>
        </xacro:if>
      </xacro:if>
      <dynamics damping="1.0" friction="0.0"/>
    </joint>

    <link name="${prefix}upper_arm_link">
      <inertial>
        <origin xyz="0.304 0.0 -0.03"
                  rpy="0 0 0" />
        <mass value="11.90" />
        <inertia ixx="0.0305"
                  ixy="0"
                  ixz="0"
                  iyy="0.4505"
                  iyz="0"
                  izz="0.0095" />
      </inertial>
      <visual>
        <origin xyz="0 0 0" rpy="0 0 0" />
        <geometry>
          <mesh filename="./meshes/aubo_i5/visual/upperArm_Link.DAE" />
        </geometry>
        <material name="">
          <color rgba="1 1 1 1" />
        </material>
      </visual>
      <collision>
        <origin xyz="0 0 0" rpy="0 0 0" />
        <geometry>
          <mesh filename="./meshes/aubo_i5/collision/upperArm_Link.STL" />
        </geometry>
      </collision>
    </link>

    <joint name="${prefix}elbow_joint" type="revolute">
      <origin xyz="0.408 0 0" rpy="-3.1416 -5.1632E-18 -5.459E-16" />
      <parent link="${prefix}upper_arm_link" />
      <child link="${prefix}forearm_link" />
      <axis xyz="0 0 1" />
      <xacro:unless value="${joint_limited}">
        <limit lower="${-pi}" upper="${pi}" effort="150.0" velocity="3.15"/>
        <xacro:if value="${safety_limits}">
          <safety_controller soft_lower_limit="${-2.0 * pi + safety_pos_margin}" soft_upper_limit="${2.0 * pi - safety_pos_margin}" k_position="${safety_k_position}" k_velocity="0.0"/>
        </xacro:if>
      </xacro:unless>
      <xacro:if value="${joint_limited}">
        <limit lower="${elbow_joint_lower_limit}" upper="${elbow_joint_upper_limit}" effort="150.0" velocity="3.15"/>
        <xacro:if value="${safety_limits}">
          <safety_controller soft_lower_limit="${elbow_joint_lower_limit + safety_pos_margin}" soft_upper_limit="${elbow_joint_upper_limit - safety_pos_margin}" k_position="${safety_k_position}" k_velocity="0.0"/>
        </xacro:if>
      </xacro:if>
      <dynamics damping="1.0" friction="0.0"/>
    </joint>

    <link name="${prefix}forearm_link">
      <inertial>
        <origin xyz="0.415 0.0 0.0992"
                  rpy="0 0 0" />
        <mass  value="3.3" />
        <inertia ixx="0.0033"
                  ixy="0"
                  ixz="0.0009"
                  iyy="0.0575"
                  iyz="0"
                  izz="0.0565" />
      </inertial>
      <visual>
        <origin xyz="0 0 0" rpy="0 0 0" />
        <geometry>
          <mesh filename="./meshes/aubo_i5/visual/foreArm_Link.DAE" />
        </geometry>
        <material name="">
          <color rgba="1 1 1 1" />
        </material>
      </visual>
      <collision>
        <origin xyz="0 0 0" rpy="0 0 0" />
        <geometry>
          <mesh filename="./meshes/aubo_i5/collision/foreArm_Link.STL" />
        </geometry>
      </collision>
    </link>

    <joint name="${prefix}wrist_1_joint" type="revolute">
      <origin xyz="0.376 0 0" rpy="3.1416 -1.8323E-15 1.5708" />
      <parent link="${prefix}forearm_link" />
      <child link="${prefix}wrist_1_link" />
      <axis xyz="0 0 1" />
      <xacro:unless value="${joint_limited}">
        <limit lower="${-2.0 * pi}" upper="${2.0 * pi}" effort="54.0" velocity="3.2"/>
        <xacro:if value="${safety_limits}">
          <safety_controller soft_lower_limit="${-2.0 * pi + safety_pos_margin}" soft_upper_limit="${2.0 * pi - safety_pos_margin}" k_position="${safety_k_position}" k_velocity="0.0"/>
        </xacro:if>
      </xacro:unless>
      <xacro:if value="${joint_limited}">
        <limit lower="${wrist_1_lower_limit}" upper="${wrist_1_upper_limit}" effort="54.0" velocity="3.2"/>
        <xacro:if value="${safety_limits}">
          <safety_controller soft_lower_limit="${wrist_1_lower_limit + safety_pos_margin}" soft_upper_limit="${wrist_1_upper_limit - safety_pos_margin}" k_position="${safety_k_position}" k_velocity="0.0"/>
        </xacro:if>
      </xacro:if>
      <dynamics damping="1.0" friction="0.0"/>
    </joint>

    <link name="${prefix}wrist_1_link">
      <inertial>
        <origin xyz="0.0 0.0028 -0.003"
                  rpy="0 0 0" />
        <mass value="1.62" />
        <inertia ixx="0.0023"
                  ixy="0"
                  ixz="0"
                  iyy="0.0013"
                  iyz="0.0"
                  izz="0.0022" />
      </inertial>
      <visual>
        <origin xyz="0 0 0" rpy="0 0 0" />
        <geometry>
          <mesh filename="./meshes/aubo_i5/visual/wrist1_Link.DAE" />
        </geometry>
        <material name="">
          <color rgba="1 1 1 1" />
        </material>
      </visual>
      <collision>
        <origin xyz="0 0 0" rpy="0 0 0" />
        <geometry>
          <mesh filename="./meshes/aubo_i5/collision/wrist1_Link.STL" />
        </geometry>
      </collision>
    </link>
    <joint name="${prefix}wrist_2_joint" type="revolute">
      <origin xyz="0 0.1025 0" rpy="-1.5708 -1.8709E-15 -1.6653E-16" />
      <parent link="${prefix}wrist_1_link" />
      <child link="${prefix}wrist_2_link" />
      <axis xyz="0 0 1" />
      <xacro:unless value="${joint_limited}">
        <limit lower="${-2.0 * pi}" upper="${2.0 * pi}" effort="54.0" velocity="3.2"/>
        <xacro:if value="${safety_limits}">
          <safety_controller soft_lower_limit="${-2.0 * pi + safety_pos_margin}" soft_upper_limit="${2.0 * pi - safety_pos_margin}" k_position="${safety_k_position}" k_velocity="0.0"/>
        </xacro:if>
      </xacro:unless>
      <xacro:if value="${joint_limited}">
        <limit lower="${wrist_2_lower_limit}" upper="${wrist_2_upper_limit}" effort="54.0" velocity="3.2"/>
        <xacro:if value="${safety_limits}">
          <safety_controller soft_lower_limit="${wrist_2_lower_limit + safety_pos_margin}" soft_upper_limit="${wrist_2_upper_limit - safety_pos_margin}" k_position="${safety_k_position}" k_velocity="0.0"/>
        </xacro:if>
      </xacro:if>
      <dynamics damping="0.0" friction="0.0"/>
    </joint>

    <link name="${prefix}wrist_2_link">
      <inertial>
        <origin xyz="0.0 -0.0028 -0.003"
                  rpy="0 0 0" />
        <mass value="1.62" />
        <inertia ixx="0.0023"
                  ixy="0"
                  ixz="0"
                  iyy="0.0013"
                  iyz="0.0"
                  izz="0.0022" />
      </inertial>
      <visual>
        <origin xyz="0 0 0" rpy="0 0 0" />
        <geometry>
          <mesh filename="./meshes/aubo_i5/visual/wrist2_Link.DAE" />
        </geometry>
        <material name="">
          <color rgba="1 1 1 1" />
        </material>
      </visual>
      <collision>
        <origin xyz="0 0 0" rpy="0 0 0" />
        <geometry>
          <mesh filename="./meshes/aubo_i5/collision/wrist2_Link.STL" />
        </geometry>
      </collision>
    </link>

    <joint name="${prefix}wrist_3_joint" type="revolute">
      <origin xyz="0 -0.094 0" rpy="1.5708 0 1.7907E-15" />
      <parent link="${prefix}wrist_2_link" />
      <child link="${prefix}wrist_3_link" />
      <axis xyz="0 0 1" />
      <xacro:unless value="${joint_limited}">
        <limit effort="0" lower="-6.2831" upper="6.2831" velocity="6.1959" />
        <xacro:if value="${safety_limits}">
          <safety_controller soft_lower_limit="${-2.0 * pi + safety_pos_margin}" soft_upper_limit="${2.0 * pi - safety_pos_margin}" k_position="${safety_k_position}" k_velocity="0.0"/>
        </xacro:if>
      </xacro:unless>
      <xacro:if value="${joint_limited}">
        <limit lower="${wrist_3_lower_limit}" upper="${wrist_3_upper_limit}" effort="54.0" velocity="3.2"/>
        <xacro:if value="${safety_limits}">
          <safety_controller soft_lower_limit="${wrist_3_lower_limit + safety_pos_margin}" soft_upper_limit="${wrist_3_upper_limit - safety_pos_margin}" k_position="${safety_k_position}" k_velocity="0.0"/>
        </xacro:if>
      </xacro:if>
      <dynamics damping="0.0" friction="0.0"/>
    </joint>

    <link name="${prefix}wrist_3_link">
      <inertial>
      <origin xyz="0.0 0.0 -0.0071"
                rpy="0 0 0" />
      <mass value="0.40" />
      <inertia ixx="0.013939"
                ixy="0"
                ixz="0"
                iyy="0.013988"
                iyz="0.0"
                izz="0.0224092" />
      </inertial>
      <visual>
        <origin xyz="0 0 0" rpy="0 0 0" />
        <geometry>
          <mesh filename="./meshes/aubo_i5/visual/wrist3_Link.DAE" />
        </geometry>
        <material name="">
          <color rgba="1 1 1 1" />
        </material>
      </visual>
      <collision>
        <origin xyz="0 0 0" rpy="0 0 0" />
        <geometry>
          <mesh filename="./meshes/aubo_i5/collision/wrist3_Link.STL" />
        </geometry>
      </collision>
    </link>


    <xacro:ur_arm_transmission prefix="${prefix}" hw_interface="${transmission_hw_interface}" />
    <xacro:ur_arm_gazebo prefix="${prefix}" />
    <!-- base for robot -->
    
    <!-- /////////////////////////////////   i5 pedestal_Link   ////////////////////////////////////// -->
    <link name="${prefix}pedestal_Link">
      <visual>
        <geometry>
          <mesh filename="./meshes/aubo_i5/collision/pedestal.STL" scale="1 1 1" />
        </geometry>
      </visual>
    </link>

    <joint name="${prefix}pedestal_joint" type="fixed">
      <parent link="${prefix}pedestal_Link"/>
      <child link="${prefix}base_link"/>
      <origin xyz="0.0 0.0 0.402" rpy="0.0 0.0 ${-pi/6}" />
    </joint>
    <!--tool link -->
    <link name='${prefix}tool_link'>
      <visual>
        <geometry>
         <mesh filename="./meshes/aubo_i5/i5tool.STL" scale='0.001 0.001 0.001'/>
        </geometry>
      </visual>
    </link>

    <joint name="${prefix}tool_joint" type="fixed">
      <parent link="${prefix}wrist_3_link"/>
      <child link="${prefix}tool_link"/>
      <origin xyz="0.0 0.0 0.0" rpy="0.0 0.0 ${-pi/2} " />
    </joint>

  </xacro:macro>
</robot>
