<?xml version="1.0"?>
<robot xmlns:xacro="http://wiki.ros.org/xacro">

  <!--
  Author: Kelsey Hawkins
  Contributers: Jimmy Da Silva, Ajit Krisshna N L, Muhammad Asif Rana
-->
  <xacro:include filename="./common_materials.xacro"/>

  <xacro:macro name="m710ic45_robot" params="prefix">

    <link name="${prefix}base_link">
      <visual>
        <origin xyz="0 0 1" rpy="0 0 0"/>
        <geometry>
          <mesh filename="./meshes/m710ic50/visual/base_link.stl"/>
        </geometry>
        <xacro:material_fanuc_black />
      </visual>
      <collision>
        <origin xyz="0 0 0" rpy="0 0 0"/>
        <geometry>
          <mesh filename="./meshes/m710ic50/collision/base_link.stl"/>
        </geometry>
      </collision>
    </link>

    <link name="${prefix}shoulder_link">
      <visual>
        <origin xyz="0 0 0" rpy="0 0 0"/>
        <geometry>
          <mesh filename="./meshes/m710ic50/visual/link_1.stl"/>
        </geometry>
        <xacro:material_fanuc_yellow />
      </visual>
      <collision>
        <origin xyz="0 0 0" rpy="0 0 0"/>
        <geometry>
          <mesh filename="./meshes/m710ic50/collision/link_1.stl"/>
        </geometry>
      </collision>
    </link>

    <link name="${prefix}upper_arm_link">
      <visual>
        <origin xyz="0 0 0" rpy="0 0 0"/>
        <geometry>
          <mesh filename="./meshes/m710ic45m/visual/link_2.stl"/>
        </geometry>
        <xacro:material_fanuc_yellow />
      </visual>
      <collision>
        <origin xyz="0 0 0" rpy="0 0 0"/>
        <geometry>
          <mesh filename="./meshes/m710ic45m/collision/link_2.stl"/>
        </geometry>
      </collision>
    </link>

    <link name="${prefix}forearm_link">
      <visual>
        <origin xyz="0 0 0" rpy="0 0 0"/>
        <geometry>
          <mesh filename="./meshes/m710ic50/visual/link_3.stl"/>
        </geometry>
        <xacro:material_fanuc_yellow />
      </visual>
      <collision>
        <origin xyz="0 0 0" rpy="0 0 0"/>
        <geometry>
          <mesh filename="./meshes/m710ic50/collision/link_3.stl"/>
        </geometry>
      </collision>
    </link>

    <link name="${prefix}wrist_1_link">
      <visual>
        <origin xyz="0 0 0" rpy="0 0 0"/>
        <geometry>
          <mesh filename="./meshes/m710ic45m/visual/link_4.stl"/>
        </geometry>
        <xacro:material_fanuc_yellow />
      </visual>
      <collision>
        <origin xyz="0 0 0" rpy="0 0 0"/>
        <geometry>
          <mesh filename="./meshes/m710ic45m/collision/link_4.stl"/>
        </geometry>
      </collision>
    </link>


    <link name="${prefix}wrist_2_link">
      <visual>
        <origin xyz="0 0 0" rpy="0 0 0"/>
        <geometry>
          <mesh filename="./meshes/m710ic50/visual/link_5.stl"/>
        </geometry>
        <xacro:material_fanuc_yellow />
      </visual>
      <collision>
        <origin xyz="0 0 0" rpy="0 0 0"/>
        <geometry>
          <mesh filename="./meshes/m710ic50/collision/link_5.stl"/>
        </geometry>
      </collision>
    </link>

    <link name="${prefix}wrist_3_link">
      <visual>
        <origin xyz="0 0 0" rpy="0 0 0"/>
        <geometry>
          <mesh filename="./meshes/m710ic50/visual/link_6.stl"/>
        </geometry>
        <xacro:material_fanuc_black />
      </visual>
      <collision>
        <origin xyz="0 0 0" rpy="0 0 0"/>
        <geometry>
          <mesh filename="./meshes/m710ic50/collision/link_6.stl"/>
        </geometry>
      </collision>
    </link>

    <!-- base for robot -->
    <link name="${prefix}fanucbase">
      <inertial>
        <origin rpy="0 0 0" xyz="-2.7535E-06 0.00054789 0.02299"/>
        <mass value="3.2345e+01"/>
        <inertia ixx="0.0029215E-04" ixy="2.2046E-07" ixz="-3.4773E-08" iyy="0.0028546E-04" iyz="-7.6362E-06" izz="0.000051176"/>
      </inertial>
      <visual>
        <origin xyz="0 0 0" rpy="0 0 0"/>
        <geometry>
          <mesh filename="./meshes/m710ic50/visual/base.dae"/>
        </geometry>
        <material name="">
          <color rgba="0.15 0.15 0.15 1.0"/>
        </material>
      </visual>
      <collision>
        <origin xyz="0 0 0" rpy="0 0 0"/>
        <geometry>
          <mesh filename="./meshes/m710ic50/visual/base.STL"/>
        </geometry>
      </collision>
    </link>

    <!--tool link -->
    <link name="${prefix}tool0">
      <inertial>
        <origin rpy="0 0 0" xyz="-2.7535E-06 0.00054789 0.02299"/>
        <mass value="3.2345e-03"/>
        <inertia ixx="0.0029215E-04" ixy="2.2046E-07" ixz="-3.4773E-08" iyy="0.0028546E-04" iyz="-7.6362E-06" izz="0.000051176"/>
      </inertial>
      <visual>
        <origin xyz="0 0 0" rpy="0 0 0"/>
        <geometry>
          <mesh filename="./meshes/m710ic50/visual/fanuctool.dae"/>
        </geometry>
        <material name="">
          <color rgba="0.15 0.15 0.15 1.0"/>
        </material>
      </visual>
      <collision>
        <origin xyz="0 0 0" rpy="0 0 0"/>
        <geometry>
          <mesh filename="./meshes/m710ic50/collision/fanuctool.STL"/>
        </geometry>
      </collision>
    </link>

    <joint name="${prefix}shoulder_pan_joint" type="revolute">
      <origin rpy="0 0 0" xyz="0 0 1.565"/>
      <parent link="${prefix}base_link" />
      <child link = "${prefix}shoulder_link" />
      <axis xyz="0 0 1" />
      <limit effort="0" lower="-3.1415" upper="3.1415" velocity="3.0543" />
    </joint>

    <joint name="${prefix}shoulder_lift_joint" type="revolute">
      <origin rpy="0 0 0" xyz="0.150 0 0"/>
      <parent link="${prefix}shoulder_link" />
      <child link = "${prefix}upper_arm_link" />
      <axis xyz="0 1 0" />
      <limit effort="0" lower="-1.5707" upper="2.3561" velocity="3.0543" />
    </joint>

    <joint name="${prefix}elbow_joint" type="revolute">
      <origin xyz="0 0 0.870" rpy="0 0 0"/>
      <parent link="${prefix}upper_arm_link" />
      <child link = "${prefix}forearm_link" />
      <axis xyz="0 -1 0" />
      <limit effort="0" lower="-2.7925" upper="4.8869" velocity="3.0543" />
    </joint>

    <joint name="${prefix}wrist_1_joint" type="revolute">
      <origin xyz="0 0 0.170" rpy="0 0 0"/>
      <parent link="${prefix}forearm_link" />
      <child link = "${prefix}wrist_1_link" />
      <axis xyz="-1 0 0"/>
      <limit effort="0" lower="-6.2830" upper="6.2830" velocity="4.3633" />
    </joint>

    <joint name="${prefix}wrist_2_joint" type="revolute">
      <origin xyz="1.016 0 0" rpy="0 0 0"/>
      <parent link="${prefix}wrist_1_link" />
      <child link = "${prefix}wrist_2_link" />
      <axis xyz="0 -1 0"/>
      <limit effort="0" lower="-2.1816" upper="2.1816" velocity="4.3633" />
    </joint>
    <joint name="${prefix}wrist_3_joint" type="revolute">
      <origin xyz="0.375 0 0" rpy="0 0 0"/>
      <parent link="${prefix}wrist_2_link" />
      <child link = "${prefix}wrist_3_link" />
      <axis xyz="-1 0 0"/>
      <limit effort="0" lower="-6.2831" upper="6.2831" velocity="6.1959" />
    </joint>

    <joint name="${prefix}base_link_base" type="fixed">
      <origin xyz="-0.55 -0.55 0" rpy="0 0 0"/>
      <parent link="${prefix}base_link"/>
      <child link="${prefix}fanucbase"/>
    </joint>


    <joint name="${prefix}tool_joint" type="fixed">
      <origin xyz="0 0 0" rpy="0 ${-pi/12} ${pi/2}"/>
      <parent link="${prefix}wrist_3_link" />
      <child link="${prefix}tool0" />
    </joint>

  </xacro:macro>
</robot>
